<?xml version="1.0"?>
<!--
  Tracer robot model with LiDAR sensors
  This file is a clean version of tracer_v1_aycbs.xacro
-->
<robot name="tracer_lidar" xmlns:xacro="http://ros.org/wiki/xacro">

  <!-- Base link -->
  <link name="base_link">
    <visual>
      <origin rpy="1.57 0 0" xyz="0 0 0"/>
      <geometry>
        <mesh filename="package://tracer_description/meshes/tracer_base_link_no_wheel.dae"/>
      </geometry>
    </visual>
    <collision>
      <origin rpy="1.57 0 0" xyz="0 0 0"/>
      <geometry>
        <mesh filename="package://tracer_description/meshes/tracer_base_link_no_wheel.dae"/>
      </geometry>
    </collision>
  </link>

  <!-- Inertial link for physics simulation -->
  <link name="inertial_link">
    <inertial>
      <mass value="132.3898489950015"/>
      <origin xyz="0.015 0.0231316650320557 0"/>
      <inertia ixx="0.185196122711036" ixy="4.30144213829512E-08" ixz="5.81037523686401E-08" 
               iyy="0.364893736238929" iyz="-0.000386720198091934" izz="0.223868521722778"/>
    </inertial>
  </link>

  <joint name="inertial_joint" type="fixed">
    <origin rpy="0 0 0" xyz="0 0 0"/>
    <parent link="base_link"/>
    <child link="inertial_link"/>
  </joint>

  <!-- Front LiDAR -->
  <link name="front_lidar_link">
    <inertial>
      <mass value="0.1"/>
      <origin xyz="0 0 0" rpy="0 0 0"/>
      <inertia ixx="0.01" ixy="0" ixz="0" iyy="0.01" iyz="0" izz="0.01"/>
    </inertial>
    <visual>
      <geometry>
        <cylinder radius="0.05" length="0.02"/>
      </geometry>
    </visual>
  </link>

  <joint name="front_lidar_joint" type="fixed">
    <parent link="base_link"/>
    <child link="front_lidar_link"/>
    <origin xyz="0.3 0 0.05" rpy="0 0 0"/>
  </joint>

  <gazebo reference="front_lidar_link">
    <sensor name="front_lidar_sensor" type="ray">
      <pose>0 0 0 0 0 0</pose>
      <visualize>true</visualize>
      <update_rate>20</update_rate>
      <ray>
        <scan>
          <horizontal>
            <samples>540</samples>
            <resolution>1</resolution>
            <min_angle>-3.14</min_angle>
            <max_angle>3.14</max_angle>
          </horizontal>
        </scan>
        <range>
          <min>0.1</min>
          <max>30.0</max>
          <resolution>0.01</resolution>
        </range>
      </ray>
      <plugin name="front_lidar_plugin" filename="libgazebo_ros_laser.so">
        <topicName>/front_lidar</topicName>
        <frameName>front_lidar_link</frameName>
      </plugin>
    </sensor>
  </gazebo>

  <!-- Rear LiDAR -->
  <link name="rear_lidar_link">
    <inertial>
      <mass value="0.1"/>
      <origin xyz="0 0 0" rpy="0 0 0"/>
      <inertia ixx="0.01" ixy="0" ixz="0" iyy="0.01" iyz="0" izz="0.01"/>
    </inertial>
    <visual>
      <geometry>
        <cylinder radius="0.05" length="0.02"/>
      </geometry>
    </visual>
  </link>

  <joint name="rear_lidar_joint" type="fixed">
    <parent link="base_link"/>
    <child link="rear_lidar_link"/>
    <origin xyz="-0.3 0 0.05" rpy="0 0 3.14159"/>
  </joint>

  <gazebo reference="rear_lidar_link">
    <sensor name="rear_lidar_sensor" type="ray">
      <pose>0 0 0 0 0 0</pose>
      <visualize>true</visualize>
      <update_rate>20</update_rate>
      <ray>
        <scan>
          <horizontal>
            <samples>540</samples>
            <resolution>1</resolution>
            <min_angle>-2.35619</min_angle>
            <max_angle>2.35619</max_angle>
          </horizontal>
        </scan>
        <range>
          <min>0.1</min>
          <max>30.0</max>
          <resolution>0.01</resolution>
        </range>
      </ray>
      <plugin name="rear_lidar_plugin" filename="libgazebo_ros_laser.so">
        <topicName>/rear_lidar</topicName>
        <frameName>rear_lidar_link</frameName>
      </plugin>
    </sensor>
  </gazebo>

  <!-- IMU Sensor -->
  <link name="imu_link">
   <inertial>
    <mass value="0.1"/>
    <origin xyz="0 0 0" rpy="0 0 0"/>
    <inertia ixx="0.01" ixy="0" ixz="0" iyy="0.01" iyz="0" izz="0.01"/>
   </inertial>
   <visual>
    <geometry>
      <box size="0.02 0.02 0.02"/>
    </geometry>
   </visual>
  </link>

  <joint name="imu_joint" type="fixed">
   <parent link="base_link"/>
   <child link="imu_link"/>
   <origin xyz="0 0 0.05" rpy="0 0 0"/>
  </joint>

  <gazebo reference="imu_link">
    <gravity>true</gravity>
    <sensor name="imu_sensor" type="imu">
      <always_on>true</always_on>
      <update_rate>100</update_rate>
      <visualize>true</visualize>
      <topic>/imu/data</topic>
      <plugin filename="libgazebo_ros_imu_sensor.so" name="imu_plugin">
        <topicName>/imu/data</topicName>
        <bodyName>imu_link</bodyName>
        <updateRateHZ>100.0</updateRateHZ>
        <gaussianNoise>0.001745</gaussianNoise>
        <xyzOffset>0 0 0.05</xyzOffset>
        <rpyOffset>0 0 0</rpyOffset>
        <frameName>imu_link</frameName>
        <initialOrientationAsReference>false</initialOrientationAsReference>
      </plugin>
      <pose>0 0 0.05 0 0 0</pose>
    </sensor>
  </gazebo>

  <!-- Right Wheel -->
  <link name="right_wheel_link">
    <inertial>
      <mass value="6"/>
      <origin xyz="0 0 0"/>
      <inertia ixx="0.7171" ixy="0" ixz="0" iyy="0.1361" iyz="0" izz="0.7171"/>
    </inertial>
    <visual>
      <origin rpy="0 0 0" xyz="0 0 0"/>
      <geometry>
        <mesh filename="package://tracer_description/meshes/tracer_wheel.dae"/>
      </geometry>
    </visual>
    <collision>
      <origin rpy="0 0 0" xyz="0 0 0"/>
      <geometry>
        <mesh filename="package://tracer_description/meshes/tracer_wheel.dae"/>
      </geometry>
    </collision>
  </link>

  <joint name="right_wheel" type="continuous">
    <parent link="base_link"/>
    <child link="right_wheel_link"/>
    <origin rpy="0 0 0" xyz="0 -0.17 -0.082"/>
    <axis rpy="0 0 0" xyz="0 1 0"/>
  </joint>

  <!-- Left Wheel -->
  <link name="left_wheel_link">
    <inertial>
      <mass value="6"/>
      <origin xyz="0 0 0"/>
      <inertia ixx="0.7171" ixy="0" ixz="0" iyy="0.1361" iyz="0" izz="0.7171"/>
    </inertial>
    <visual>
      <origin rpy="0 0 0" xyz="0 0 0"/>
      <geometry>
        <mesh filename="package://tracer_description/meshes/tracer_wheel.dae"/>
      </geometry>
    </visual>
    <collision>
      <origin rpy="0 0 0" xyz="0 0 0"/>
      <geometry>
        <mesh filename="package://tracer_description/meshes/tracer_wheel.dae"/>
      </geometry>
    </collision>
  </link>

  <joint name="left_wheel" type="continuous">
    <parent link="base_link"/>
    <child link="left_wheel_link"/>
    <origin rpy="3.14 0 0" xyz="0 0.17 -0.082"/>
    <axis rpy="0 0 0" xyz="0 1 0"/>
  </joint>

  <!-- Castor wheels (front left, front right, rear right, rear left) -->
  <!-- FL Castor -->
  <link name="fl_castor_link">
    <inertial>
      <mass value="1"/>
      <origin xyz="0 0 0"/>
      <inertia ixx="0.7171" ixy="0" ixz="0" iyy="0.1361" iyz="0" izz="0.7171"/>
    </inertial>
    <visual>
      <geometry>
        <mesh filename="package://tracer_description/meshes/castor_joint.dae"/>
      </geometry>
    </visual>
  </link>

  <joint name="fl_castor_wheel" type="continuous">
    <origin rpy="-1.57 0 0" xyz="0.18955 0.17 -0.0380886"/>
    <parent link="base_link"/>
    <child link="fl_castor_link"/>
    <axis rpy="0 0 0" xyz="0 1 0"/>
  </joint>

  <!-- FR Castor -->
  <link name="fr_castor_link">
    <inertial>
      <mass value="1"/>
      <origin xyz="0 0 0"/>
      <inertia ixx="0.7171" ixy="0" ixz="0" iyy="0.1361" iyz="0" izz="0.7171"/>
    </inertial>
    <visual>
      <geometry>
        <mesh filename="package://tracer_description/meshes/castor_joint.dae"/>
      </geometry>
    </visual>
  </link>

  <joint name="fr_castor_wheel" type="continuous">
    <origin rpy="-1.57 0 0" xyz="0.18955 -0.17 -0.0380886"/>
    <parent link="base_link"/>
    <child link="fr_castor_link"/>
    <axis rpy="0 0 0" xyz="0 1 0"/>
  </joint>

  <!-- RR Castor -->
  <link name="rr_castor_link">
    <inertial>
      <mass value="1"/>
      <origin xyz="0 0 0"/>
      <inertia ixx="0.7171" ixy="0" ixz="0" iyy="0.1361" iyz="0" izz="0.7171"/>
    </inertial>
    <visual>
      <geometry>
        <mesh filename="package://tracer_description/meshes/castor_joint.dae"/>
      </geometry>
    </visual>
  </link>

  <joint name="rr_castor_wheel" type="continuous">
    <origin rpy="-1.57 0 0" xyz="-0.18955 -0.17 -0.0380886"/>
    <parent link="base_link"/>
    <child link="rr_castor_link"/>
    <axis rpy="0 0 0" xyz="0 1 0"/>
  </joint>

  <!-- RL Castor -->
  <link name="rl_castor_link">
    <inertial>
      <mass value="1"/>
      <origin xyz="0 0 0"/>
      <inertia ixx="0.7171" ixy="0" ixz="0" iyy="0.1361" iyz="0" izz="0.7171"/>
    </inertial>
    <visual>
      <geometry>
        <mesh filename="package://tracer_description/meshes/castor_joint.dae"/>
      </geometry>
    </visual>
  </link>

  <joint name="rl_castor_wheel" type="continuous">
    <origin rpy="-1.57 0 0" xyz="-0.18955 0.17 -0.0380886"/>
    <parent link="base_link"/>
    <child link="rl_castor_link"/>
    <axis rpy="0 0 0" xyz="0 1 0"/>
  </joint>

  <!-- Castor wheels -->
  <link name="fl_wheel_link">
    <inertial>
      <mass value="1"/>
      <origin xyz="0 0 0"/>
      <inertia ixx="0.3131" ixy="0" ixz="0" iyy="0.3131" iyz="0" izz="0.1361"/>
    </inertial>
    <visual>
      <geometry>
        <mesh filename="package://tracer_description/meshes/castor.dae"/>
      </geometry>
    </visual>
    <collision>
      <origin rpy="0 0 0" xyz="0 0 0"/>
      <geometry>
        <mesh filename="package://tracer_description/meshes/castor.dae"/>
      </geometry>
    </collision>
  </link>

  <joint name="fl_wheel" type="continuous">
    <parent link="fl_castor_link"/>
    <child link="fl_wheel_link"/>
    <dynamics damping="0.0" friction="0.0"/>
    <origin rpy="0 0 0" xyz="-0.0218084 0.067 0"/>
    <axis rpy="0 0 0" xyz="0 0 1"/>
  </joint>

  <link name="fr_wheel_link">
    <inertial>
      <mass value="1"/>
      <origin xyz="0 0 0"/>
      <inertia ixx="0.3131" ixy="0" ixz="0" iyy="0.3131" iyz="0" izz="0.1361"/>
    </inertial>
    <visual>
      <geometry>
        <mesh filename="package://tracer_description/meshes/castor.dae"/>
      </geometry>
    </visual>
    <collision>
      <origin rpy="0 0 0" xyz="0 0 0"/>
      <geometry>
        <mesh filename="package://tracer_description/meshes/castor.dae"/>
      </geometry>
    </collision>
  </link>

  <joint name="fr_wheel" type="continuous">
    <parent link="fr_castor_link"/>
    <child link="fr_wheel_link"/>
    <dynamics damping="0.0" friction="0.0"/>
    <origin rpy="0 0 0" xyz="-0.0218084 0.067 0"/>
    <axis rpy="0 0 0" xyz="0 0 1"/>
  </joint>

  <link name="rr_wheel_link">
    <inertial>
      <mass value="1"/>
      <origin xyz="0 0 0"/>
      <inertia ixx="0.3131" ixy="0" ixz="0" iyy="0.3131" iyz="0" izz="0.1361"/>
    </inertial>
    <visual>
      <geometry>
        <mesh filename="package://tracer_description/meshes/castor.dae"/>
      </geometry>
    </visual>
    <collision>
      <origin rpy="0 0 0" xyz="0 0 0"/>
      <geometry>
        <mesh filename="package://tracer_description/meshes/castor.dae"/>
      </geometry>
    </collision>
  </link>

  <joint name="rr_wheel" type="continuous">
    <parent link="rr_castor_link"/>
    <child link="rr_wheel_link"/>
    <dynamics damping="0.0" friction="0.0"/>
    <origin rpy="0 0 0" xyz="-0.0218084 0.067 0"/>
    <axis rpy="0 0 0" xyz="0 0 1"/>
  </joint>

  <link name="rl_wheel_link">
    <inertial>
      <mass value="1"/>
      <origin xyz="0 0 0"/>
      <inertia ixx="0.3131" ixy="0" ixz="0" iyy="0.3131" iyz="0" izz="0.1361"/>
    </inertial>
    <visual>
      <geometry>
        <mesh filename="package://tracer_description/meshes/castor.dae"/>
      </geometry>
    </visual>
    <collision>
      <origin rpy="0 0 0" xyz="0 0 0"/>
      <geometry>
        <mesh filename="package://tracer_description/meshes/castor.dae"/>
      </geometry>
    </collision>
  </link>

  <joint name="rl_wheel" type="continuous">
    <parent link="rl_castor_link"/>
    <child link="rl_wheel_link"/>
    <dynamics damping="0.0" friction="0.0"/>
    <origin rpy="0 0 0" xyz="-0.0218084 0.067 0"/>
    <axis rpy="0 0 0" xyz="0 0 1"/>
  </joint>

  <!-- Ground truth for simulation -->
  <gazebo>
    <plugin name="ground_truth" filename="libgazebo_ros_p3d.so">
      <frameName>world</frameName>
      <topicName>ground_truth/state</topicName>
      <bodyName>base_link</bodyName>
      <updateRate>50.0</updateRate>
      <gaussianNoise>0.0</gaussianNoise>
    </plugin>
  </gazebo>

  <!-- Gazebo plugins and control interfaces -->
  <gazebo>
    <plugin name="gazebo_ros_control" filename="libgazebo_ros_control.so">
      <robotNamespace>/</robotNamespace>
    </plugin>
  </gazebo>

  <!-- Transmissions for ROS Control -->
  <transmission name="right_wheel_trans" type="SimpleTransmission">
    <type>transmission_interface/SimpleTransmission</type>
    <actuator name="right_wheel_motor">
      <mechanicalReduction>1</mechanicalReduction>
    </actuator>
    <joint name="right_wheel">
      <hardwareInterface>hardware_interface/VelocityJointInterface</hardwareInterface>
    </joint>
  </transmission>
  
  <transmission name="left_wheel_trans" type="SimpleTransmission">
    <type>transmission_interface/SimpleTransmission</type>
    <actuator name="left_wheel_motor">
      <mechanicalReduction>1</mechanicalReduction>
    </actuator>
    <joint name="left_wheel">
      <hardwareInterface>hardware_interface/VelocityJointInterface</hardwareInterface>
    </joint>
  </transmission>

  <!-- Material properties for simulation -->
  <gazebo>
    <mu1 value="1.0"/>
    <mu2 value="0.9"/>
    <kp value="10000000.0"/>
    <kd value="1.0"/>
    <fdir1 value="1 0 0"/>
    <minDepth value="0.001"/>
    <maxContacts value="64"/>
  </gazebo>

</robot> 